Traceback (most recent call last):
  File "/usr/local/lib/python3.9/dist-packages/adafruit_bus_device/i2c_device.py", line 176, in __probe_for_device
    self.i2c.writeto(self.device_address, b"")
  File "/usr/local/lib/python3.9/dist-packages/busio.py", line 175, in writeto
    return self._i2c.writeto(address, buffer, stop=stop)
  File "/usr/local/lib/python3.9/dist-packages/adafruit_blinka/microcontroller/generic_linux/i2c.py", line 52, in writeto
    self._i2c_bus.write_bytes(address, buffer[start:end])
  File "/usr/local/lib/python3.9/dist-packages/Adafruit_PureIO/smbus.py", line 314, in write_bytes
    self._device.write(buf)
OSError: [Errno 121] Remote I/O error

During handling of the above exception, another exception occurred:

Traceback (most recent call last):
  File "/usr/local/lib/python3.9/dist-packages/adafruit_bus_device/i2c_device.py", line 182, in __probe_for_device
    self.i2c.readfrom_into(self.device_address, result)
  File "/usr/local/lib/python3.9/dist-packages/busio.py", line 165, in readfrom_into
    return self._i2c.readfrom_into(address, buffer, stop=stop)
  File "/usr/local/lib/python3.9/dist-packages/adafruit_blinka/microcontroller/generic_linux/i2c.py", line 59, in readfrom_into
    readin = self._i2c_bus.read_bytes(address, end - start)
  File "/usr/local/lib/python3.9/dist-packages/Adafruit_PureIO/smbus.py", line 181, in read_bytes
    return self._device.read(number)
OSError: [Errno 121] Remote I/O error

During handling of the above exception, another exception occurred:

Traceback (most recent call last):
  File "/home/ramsandrockets/accelerometer.py", line 6, in <module>
    accelerometer = adafruit_adxl34x.ADXL345(i2c)
  File "/usr/local/lib/python3.9/dist-packages/adafruit_adxl34x.py", line 182, in __init__
    self._i2c = i2c_device.I2CDevice(i2c, address)
  File "/usr/local/lib/python3.9/dist-packages/adafruit_bus_device/i2c_device.py", line 63, in __init__
    self.__probe_for_device()
  File "/usr/local/lib/python3.9/dist-packages/adafruit_bus_device/i2c_device.py", line 185, in __probe_for_device
    raise ValueError("No I2C device at address: 0x%x" % self.device_address)
ValueError: No I2C device at address: 0x53
Traceback (most recent call last):
  File "/usr/local/lib/python3.9/dist-packages/adafruit_bus_device/i2c_device.py", line 176, in __probe_for_device
    self.i2c.writeto(self.device_address, b"")
  File "/usr/local/lib/python3.9/dist-packages/busio.py", line 175, in writeto
    return self._i2c.writeto(address, buffer, stop=stop)
  File "/usr/local/lib/python3.9/dist-packages/adafruit_blinka/microcontroller/generic_linux/i2c.py", line 52, in writeto
    self._i2c_bus.write_bytes(address, buffer[start:end])
  File "/usr/local/lib/python3.9/dist-packages/Adafruit_PureIO/smbus.py", line 314, in write_bytes
    self._device.write(buf)
OSError: [Errno 121] Remote I/O error

During handling of the above exception, another exception occurred:

Traceback (most recent call last):
  File "/usr/local/lib/python3.9/dist-packages/adafruit_bus_device/i2c_device.py", line 182, in __probe_for_device
    self.i2c.readfrom_into(self.device_address, result)
  File "/usr/local/lib/python3.9/dist-packages/busio.py", line 165, in readfrom_into
    return self._i2c.readfrom_into(address, buffer, stop=stop)
  File "/usr/local/lib/python3.9/dist-packages/adafruit_blinka/microcontroller/generic_linux/i2c.py", line 59, in readfrom_into
    readin = self._i2c_bus.read_bytes(address, end - start)
  File "/usr/local/lib/python3.9/dist-packages/Adafruit_PureIO/smbus.py", line 181, in read_bytes
    return self._device.read(number)
OSError: [Errno 121] Remote I/O error

During handling of the above exception, another exception occurred:

Traceback (most recent call last):
  File "/home/ramsandrockets/accelerometer.py", line 6, in <module>
    accelerometer = adafruit_adxl34x.ADXL345(i2c)
  File "/usr/local/lib/python3.9/dist-packages/adafruit_adxl34x.py", line 182, in __init__
    self._i2c = i2c_device.I2CDevice(i2c, address)
  File "/usr/local/lib/python3.9/dist-packages/adafruit_bus_device/i2c_device.py", line 63, in __init__
    self.__probe_for_device()
  File "/usr/local/lib/python3.9/dist-packages/adafruit_bus_device/i2c_device.py", line 185, in __probe_for_device
    raise ValueError("No I2C device at address: 0x%x" % self.device_address)
ValueError: No I2C device at address: 0x53
[2023-04-15_14:17:41] Payload handler active.
[2023-04-15_14:17:41] Delaying 0 seconds...
[2023-04-15_14:17:41] Configuring pins...
[2023-04-15_14:17:41] Extending linear actuator...
[2023-04-15_14:18:12] Straightening servos...
[2023-04-15_14:18:17] Running DC motor to raise payload...
[2023-04-15_14:18:45] Orienting camera to be even with the horizon...
[2023-04-15_14:18:45] Orienting roll servo to default position...
[2023-04-15_14:18:51] ERROR: Accelerometer Disconnected
[2023-04-15_14:18:55] ERROR: Accelerometer Disconnected
[2023-04-15_14:18:55] Roll offset: 0 - Target roll servo angle: 150
Traceback (most recent call last):
  File "/usr/local/lib/python3.9/dist-packages/adafruit_bus_device/i2c_device.py", line 176, in __probe_for_device
    self.i2c.writeto(self.device_address, b"")
  File "/usr/local/lib/python3.9/dist-packages/busio.py", line 175, in writeto
    return self._i2c.writeto(address, buffer, stop=stop)
  File "/usr/local/lib/python3.9/dist-packages/adafruit_blinka/microcontroller/generic_linux/i2c.py", line 52, in writeto
    self._i2c_bus.write_bytes(address, buffer[start:end])
  File "/usr/local/lib/python3.9/dist-packages/Adafruit_PureIO/smbus.py", line 314, in write_bytes
    self._device.write(buf)
OSError: [Errno 121] Remote I/O error

During handling of the above exception, another exception occurred:

Traceback (most recent call last):
  File "/usr/local/lib/python3.9/dist-packages/adafruit_bus_device/i2c_device.py", line 182, in __probe_for_device
    self.i2c.readfrom_into(self.device_address, result)
  File "/usr/local/lib/python3.9/dist-packages/busio.py", line 165, in readfrom_into
    return self._i2c.readfrom_into(address, buffer, stop=stop)
  File "/usr/local/lib/python3.9/dist-packages/adafruit_blinka/microcontroller/generic_linux/i2c.py", line 59, in readfrom_into
    readin = self._i2c_bus.read_bytes(address, end - start)
  File "/usr/local/lib/python3.9/dist-packages/Adafruit_PureIO/smbus.py", line 181, in read_bytes
    return self._device.read(number)
OSError: [Errno 121] Remote I/O error

During handling of the above exception, another exception occurred:

Traceback (most recent call last):
  File "/home/ramsandrockets/accelerometer.py", line 6, in <module>
    accelerometer = adafruit_adxl34x.ADXL345(i2c)
  File "/usr/local/lib/python3.9/dist-packages/adafruit_adxl34x.py", line 182, in __init__
    self._i2c = i2c_device.I2CDevice(i2c, address)
  File "/usr/local/lib/python3.9/dist-packages/adafruit_bus_device/i2c_device.py", line 63, in __init__
    self.__probe_for_device()
  File "/usr/local/lib/python3.9/dist-packages/adafruit_bus_device/i2c_device.py", line 185, in __probe_for_device
    raise ValueError("No I2C device at address: 0x%x" % self.device_address)
ValueError: No I2C device at address: 0x53
Traceback (most recent call last):
  File "/usr/local/lib/python3.9/dist-packages/adafruit_bus_device/i2c_device.py", line 176, in __probe_for_device
    self.i2c.writeto(self.device_address, b"")
  File "/usr/local/lib/python3.9/dist-packages/busio.py", line 175, in writeto
    return self._i2c.writeto(address, buffer, stop=stop)
  File "/usr/local/lib/python3.9/dist-packages/adafruit_blinka/microcontroller/generic_linux/i2c.py", line 52, in writeto
    self._i2c_bus.write_bytes(address, buffer[start:end])
  File "/usr/local/lib/python3.9/dist-packages/Adafruit_PureIO/smbus.py", line 314, in write_bytes
    self._device.write(buf)
OSError: [Errno 121] Remote I/O error

During handling of the above exception, another exception occurred:

Traceback (most recent call last):
  File "/usr/local/lib/python3.9/dist-packages/adafruit_bus_device/i2c_device.py", line 182, in __probe_for_device
    self.i2c.readfrom_into(self.device_address, result)
  File "/usr/local/lib/python3.9/dist-packages/busio.py", line 165, in readfrom_into
    return self._i2c.readfrom_into(address, buffer, stop=stop)
  File "/usr/local/lib/python3.9/dist-packages/adafruit_blinka/microcontroller/generic_linux/i2c.py", line 59, in readfrom_into
    readin = self._i2c_bus.read_bytes(address, end - start)
  File "/usr/local/lib/python3.9/dist-packages/Adafruit_PureIO/smbus.py", line 181, in read_bytes
    return self._device.read(number)
OSError: [Errno 121] Remote I/O error

During handling of the above exception, another exception occurred:

Traceback (most recent call last):
  File "/home/ramsandrockets/accelerometer.py", line 6, in <module>
    accelerometer = adafruit_adxl34x.ADXL345(i2c)
  File "/usr/local/lib/python3.9/dist-packages/adafruit_adxl34x.py", line 182, in __init__
    self._i2c = i2c_device.I2CDevice(i2c, address)
  File "/usr/local/lib/python3.9/dist-packages/adafruit_bus_device/i2c_device.py", line 63, in __init__
    self.__probe_for_device()
  File "/usr/local/lib/python3.9/dist-packages/adafruit_bus_device/i2c_device.py", line 185, in __probe_for_device
    raise ValueError("No I2C device at address: 0x%x" % self.device_address)
ValueError: No I2C device at address: 0x53
[2023-04-15_14:18:56] Orienting pitch servo to default position...
[2023-04-15_14:19:01] ERROR: Accelerometer Disconnected
[2023-04-15_14:19:04] ERROR: Accelerometer Disconnected
[2023-04-15_14:19:04] Pitch offset: 0 - Target pitch servo angle: 60
mmal: Cannot read camera info, keeping the defaults for OV5647
mmal: mmal_vc_component_create: failed to create component 'vc.ril.camera' (1:ENOMEM)
mmal: mmal_component_create_core: could not create component 'vc.ril.camera' (1)
mmal: Failed to create camera component
mmal: main: Failed to create camera component
mmal: Camera is not detected. Please check carefully the camera module is installed correctly

mv: cannot stat 'temp.jpg': No such file or directory
convert-im6.q16: insufficient image data in file `[2023-04-15_14:29:07].jpg' @ error/jpeg.c/ReadJPEGImage_/1166.
convert-im6.q16: no images defined `[2023-04-15_14:29:07].jpg' @ error/convert.c/ConvertImageCommand/3229.
mmal: Cannot read camera info, keeping the defaults for OV5647
mmal: mmal_vc_component_create: failed to create component 'vc.ril.camera' (1:ENOMEM)
mmal: mmal_component_create_core: could not create component 'vc.ril.camera' (1)
mmal: Failed to create camera component
mmal: main: Failed to create camera component
mmal: Camera is not detected. Please check carefully the camera module is installed correctly

mv: cannot stat 'temp.jpg': No such file or directory
convert-im6.q16: insufficient image data in file `[2023-04-15_14:29:09].jpg' @ error/jpeg.c/ReadJPEGImage_/1166.
convert-im6.q16: no images defined `[2023-04-15_14:29:09].jpg' @ error/convert.c/ConvertImageCommand/3229.
convert-im6.q16: insufficient image data in file `[2023-04-15_14:29:09].jpg' @ error/jpeg.c/ReadJPEGImage_/1166.
convert-im6.q16: no images defined `[2023-04-15_14:29:09].jpg' @ error/convert.c/ConvertImageCommand/3229.
mmal: Cannot read camera info, keeping the defaults for OV5647
mmal: mmal_vc_component_create: failed to create component 'vc.ril.camera' (1:ENOMEM)
mmal: mmal_component_create_core: could not create component 'vc.ril.camera' (1)
mmal: Failed to create camera component
mmal: main: Failed to create camera component
mmal: Camera is not detected. Please check carefully the camera module is installed correctly

mv: cannot stat 'temp.jpg': No such file or directory
convert-im6.q16: insufficient image data in file `[2023-04-15_14:29:12].jpg' @ error/jpeg.c/ReadJPEGImage_/1166.
convert-im6.q16: no images defined `[2023-04-15_14:29:12].jpg' @ error/convert.c/ConvertImageCommand/3229.
convert-im6.q16: insufficient image data in file `[2023-04-15_14:29:12].jpg' @ error/jpeg.c/ReadJPEGImage_/1166.
convert-im6.q16: no images defined `[2023-04-15_14:29:12].jpg' @ error/convert.c/ConvertImageCommand/3229.
[2023-04-15_14:19:05] Awaiting receival of command transmission...
[2023-04-15_14:29:07] Transmission received!
[2023-04-15_14:29:07] Beginning execution of commands.
[2023-04-15_14:29:07] Executing command C3...
[2023-04-15_14:29:08] Picture taken.
[2023-04-15_14:29:08] Executing command E5...
[2023-04-15_14:29:08] Color mode activated.
[2023-04-15_14:29:08] Executing command A1...
[2023-04-15_14:29:09] Camera turned right 60 degrees.
[2023-04-15_14:29:09] Executing command G7...
[2023-04-15_14:29:09] Applied brightness filter.
[2023-04-15_14:29:09] Executing command C3...
[2023-04-15_14:29:11] Picture taken.
[2023-04-15_14:29:11] Executing command H8...
[2023-04-15_14:29:11] Removed all filters.
[2023-04-15_14:29:11] Executing command A1...
[2023-04-15_14:29:12] Camera turned right 60 degrees.
[2023-04-15_14:29:12] Executing command F6...
[2023-04-15_14:29:12] Increased image rotation by 180 degrees.
[2023-04-15_14:29:12] Executing command C3...
[2023-04-15_14:29:14] Picture taken.
[2023-04-15_14:29:14] Execution of all commands completed!
[2023-04-15_14:29:14] Lowering payload...
[2023-04-15_14:29:42] Program terminated.
